<?xml version="1.0" encoding="utf-8"?>

<robot name="asar_robot" version="1.0">
  <link name="base_link">
    <!-- <inertial>
      <origin xyz="-0.000648 -0.000166 0.084487" rpy="0 0 0" />
      <mass value="1.697" />
      <inertia ixx="0.004622" ixy="9E-06" ixz="6E-05" iyy="0.004495" iyz="9E-06" izz="0.002079" />
    </inertial> -->
    <visual>
      <origin xyz="0 0 0" rpy="0 0 0" />
      <geometry>
        <mesh filename="package://asar_description/meshes/base_link.STL" />
      </geometry>
      <material name="">
        <color rgba="0.75294 0.75294 0.75294 1" />
      </material>
    </visual>
    <collision>
      <origin xyz="0 0 0" rpy="0 0 0" />
      <geometry>
        <mesh filename="package://asar_description/meshes/base_link.STL" />
      </geometry>
    </collision>
  </link>
  <link name="shoulder_link">
    <inertial>
      <origin xyz="-2.3E-05 -0.010364 -0.07336" rpy="0 0 0" />
      <mass value="1.3773" />
      <inertia ixx="0.00457" ixy="1E-06" ixz="2E-06" iyy="0.004831" iyz="0.000448" izz="0.001409" />
    </inertial>
    <visual>
      <origin xyz="0 0 0" rpy="0 0 0" />
      <geometry>
        <mesh filename="package://asar_description/meshes/shoulder_link.STL" />
      </geometry>
      <material name="">
        <color rgba="0.75294 0.75294 0.75294 1" />
      </material>
    </visual>
    <collision>
      <origin xyz="0 0 0" rpy="0 0 0" />
      <geometry>
        <mesh filename="package://asar_description/meshes/shoulder_link.STL" />
      </geometry>
    </collision>
  </link>
  <joint name="joint_1" type="continuous">
    <origin xyz="0 0 0.15643" rpy="3.1416 2.7629E-18 -4.9305E-36" />
    <parent link="base_link" />
    <child link="shoulder_link" />
    <axis xyz="0 0 1" />
    <limit effort="39" velocity="0.8727" />
  </joint>
  <link name="half_arm_1_link">
    <inertial>
      <origin xyz="-4.4E-05 -0.09958 -0.013278" rpy="0 0 0" />
      <mass value="1.1636" />
      <inertia ixx="0.011088" ixy="5E-06" ixz="0" iyy="0.001072" iyz="-0.000691" izz="0.011255" />
    </inertial>
    <visual>
      <origin xyz="0 0 0" rpy="0 0 0" />
      <geometry>
        <mesh filename="package://asar_description/meshes/half_arm_1_link.STL" />
      </geometry>
      <material name="">
        <color rgba="0.75294 0.75294 0.75294 1" />
      </material>
    </visual>
    <collision>
      <origin xyz="0 0 0" rpy="0 0 0" />
      <geometry>
        <mesh filename="package://asar_description/meshes/half_arm_1_link.STL" />
      </geometry>
    </collision>
  </link>
  <joint name="joint_2" type="revolute">
    <origin xyz="0 0.005375 -0.12838" rpy="1.5708 2.1343E-17 -1.1102E-16" />
    <parent link="shoulder_link" />
    <child link="half_arm_1_link" />
    <axis xyz="0 0 1" />
    <limit lower="-2.41" upper="2.41" effort="39" velocity="0.8727" />
  </joint>
  <link name="half_arm_2_link">
    <inertial>
      <origin xyz="-4.4E-05 -0.006641 -0.117892" rpy="0 0 0" />
      <mass value="1.1636" />
      <inertia ixx="0.010932" ixy="0" ixz="-7E-06" iyy="0.011127" iyz="0.000606" izz="0.001043" />
    </inertial>
    <visual>
      <origin xyz="0 0 0" rpy="0 0 0" />
      <geometry>
        <mesh filename="package://asar_description/meshes/half_arm_2_link.STL" />
      </geometry>
      <material name="">
        <color rgba="0.75294 0.75294 0.75294 1" />
      </material>
    </visual>
    <collision>
      <origin xyz="0 0 0" rpy="0 0 0" />
      <geometry>
        <mesh filename="package://asar_description/meshes/half_arm_2_link.STL" />
      </geometry>
    </collision>
  </link>
  <joint name="joint_3" type="continuous">
    <origin xyz="0 -0.21038 -0.006375" rpy="-1.5708 1.2326E-32 -2.9122E-16" />
    <parent link="half_arm_1_link" />
    <child link="half_arm_2_link" />
    <axis xyz="0 0 1" />
    <limit effort="39" velocity="0.8727" />
  </joint>
  <link name="forearm_link">
    <inertial>
      <origin xyz="-1.8E-05 -0.075478 -0.015006" rpy="0 0 0" />
      <mass value="0.9302" />
      <inertia ixx="0.008147" ixy="-1E-06" ixz="0" iyy="0.000631" iyz="-0.0005" izz="0.008316" />
    </inertial>
    <visual>
      <origin xyz="0 0 0" rpy="0 0 0" />
      <geometry>
        <mesh filename="package://asar_description/meshes/forearm_link.STL" />
      </geometry>
      <material name="">
        <color rgba="0.75294 0.75294 0.75294 1" />
      </material>
    </visual>
    <collision>
      <origin xyz="0 0 0" rpy="0 0 0" />
      <geometry>
        <mesh filename="package://asar_description/meshes/forearm_link.STL" />
      </geometry>
    </collision>
  </link>
  <joint name="joint_4" type="revolute">
    <origin xyz="0 0.006375 -0.21038" rpy="1.5708 -6.6954E-17 -1.6653E-16" />
    <parent link="half_arm_2_link" />
    <child link="forearm_link" />
    <axis xyz="0 0 1" />
    <limit lower="-2.66" upper="2.66" effort="39" velocity="0.8727" />
  </joint>
  <link name="spherical_wrist_1_link">
    <inertial>
      <origin xyz="1E-06 -0.009432 -0.063883" rpy="0 0 0" />
      <mass value="0.6781" />
      <inertia ixx="0.001596" ixy="0" ixz="0" iyy="0.001607" iyz="0.000256" izz="0.000399" />
    </inertial>
    <visual>
      <origin xyz="0 0 0" rpy="0 0 0" />
      <geometry>
        <mesh filename="package://asar_description/meshes/spherical_wrist_1_link.STL" />
      </geometry>
      <material name="">
        <color rgba="0.75294 0.75294 0.75294 1" />
      </material>
    </visual>
    <collision>
      <origin xyz="0 0 0" rpy="0 0 0" />
      <geometry>
        <mesh filename="package://asar_description/meshes/spherical_wrist_1_link.STL" />
      </geometry>
    </collision>
  </link>
  <joint name="joint_5" type="continuous">
    <origin xyz="0 -0.20843 -0.006375" rpy="-1.5708 2.2204E-16 -6.373E-17" />
    <parent link="forearm_link" />
    <child link="spherical_wrist_1_link" />
    <axis xyz="0 0 1" />
    <limit effort="9" velocity="0.8727" />
  </joint>
  <link name="spherical_wrist_2_link">
    <inertial>
      <origin xyz="1E-06 -0.045483 -0.00965" rpy="0 0 0" />
      <mass value="0.6781" />
      <inertia ixx="0.001641" ixy="0" ixz="0" iyy="0.00041" iyz="-0.000278" izz="0.001641" />
    </inertial>
    <visual>
      <origin xyz="0 0 0" rpy="0 0 0" />
      <geometry>
        <mesh filename="package://asar_description/meshes/spherical_wrist_2_link.STL" />
      </geometry>
      <material name="">
        <color rgba="0.75294 0.75294 0.75294 1" />
      </material>
    </visual>
    <collision>
      <origin xyz="0 0 0" rpy="0 0 0" />
      <geometry>
        <mesh filename="package://asar_description/meshes/spherical_wrist_2_link.STL" />
      </geometry>
    </collision>
  </link>
  <joint name="joint_6" type="revolute">
    <origin xyz="0 0.00017505 -0.10593" rpy="1.5708 9.2076E-28 -8.2157E-15" />
    <parent link="spherical_wrist_1_link" />
    <child link="spherical_wrist_2_link" />
    <axis xyz="0 0 1" />
    <limit lower="-2.23" upper="2.23" effort="9" velocity="0.8727" />
  </joint>
  <link name="bracelet_link">
    <inertial>
      <origin xyz="-0.000281 -0.011402 -0.029798" rpy="0 0 0" />
      <mass value="0.5006" />
      <inertia ixx="0.000587" ixy="3E-06" ixz="3E-06" iyy="0.000369" iyz="0.000118" izz="0.000609" />
    </inertial>
    <visual>
      <origin xyz="0 0 0" rpy="0 0 0" />
      <geometry>
        <mesh filename="package://asar_description/meshes/bracelet_no_vision_link.STL" />
      </geometry>
      <material name="">
        <color rgba="0.75294 0.75294 0.75294 1" />
      </material>
    </visual>
    <collision>
      <origin xyz="0 0 0" rpy="0 0 0" />
      <geometry>
        <mesh filename="package://asar_description/meshes/bracelet_no_vision_link.STL" />
      </geometry>
    </collision>
  </link>
  <joint name="joint_7" type="continuous">
    <origin xyz="0 -0.10593 -0.00017505" rpy="-1.5708 -5.5511E-17 9.6396E-17" />
    <parent link="spherical_wrist_2_link" />
    <child link="bracelet_link" />
    <axis xyz="0 0 1" />
    <limit effort="9" velocity="0.8727" />
  </joint>

  <link
    name="forceps_base_link">
    <inertial>
      <origin
        xyz="-0.00149044162951133 3.88166641877133E-05 0.0447075908051869"
        rpy="0 0 0" />
      <mass
        value="0.298186310510585" />
      <inertia
        ixx="0.000154776223901756"
        ixy="-3.74733857377063E-07"
        ixz="1.53127145926008E-06"
        iyy="0.000144719807415472"
        iyz="-3.22842778667153E-07"
        izz="0.000229690754405414" />
    </inertial>
    <visual>
      <origin
        xyz="0 0 0"
        rpy="0 0 0" />
      <geometry>
        <mesh
          filename="package://asar_description/meshes/forceps_base_link.STL" />
      </geometry>
      <material
        name="">
        <color
          rgba="0.752941176470588 0.752941176470588 0.752941176470588 1" />
      </material>
    </visual>
    <collision>
      <origin
        xyz="0 0 0"
        rpy="0 0 0" />
      <geometry>
        <mesh
          filename="package://asar_description/meshes/forceps_base_link.STL" />
      </geometry>
    </collision>
  </link>
  <joint name="joint_robot_ee" type="fixed">
    <origin xyz="0 0 -0.0615250000000001" rpy="-3.14159265358979 0.0 0.0" />
    <parent link="bracelet_link" />
    <child link="forceps_base_link" />
    <axis xyz="0 0 1" />
  </joint>
  <link
    name="interface_link">
    <inertial>
      <origin
        xyz="3.00086145239549E-09 2.112459961582E-11 0.147402389131478"
        rpy="0 0 0" />
      <mass
        value="0.00261293291328178" />
      <inertia
        ixx="1.63505872923441E-05"
        ixy="3.8663038074946E-12"
        ixz="-3.42186336718604E-14"
        iyy="1.63509454131809E-05"
        iyz="7.48161673523837E-15"
        izz="3.57106513425572E-08" />
    </inertial>
    <visual>
      <origin
        xyz="0 0 0"
        rpy="0 0 0" />
      <geometry>
        <mesh
          filename="package://asar_description/meshes/interface_link.STL" />
      </geometry>
      <material
        name="">
        <color
          rgba="0.792156862745098 0.819607843137255 0.933333333333333 1" />
      </material>
    </visual>
    <collision>
      <origin
        xyz="0 0 0"
        rpy="0 0 0" />
      <geometry>
        <mesh
          filename="package://asar_description/meshes/interface_link.STL" />
      </geometry>
    </collision>
  </link>
  <joint
    name="joint_interface"
    type="fixed">
    <origin
      xyz="-0.00027829 0 0.13908"
      rpy="0 0 0" />
    <parent
      link="forceps_base_link" />
    <child
      link="interface_link" />
    <axis
      xyz="0 0 0" />
  </joint>
  <link
    name="pitch_link">
    <inertial>
      <origin
        xyz="2.52485481626179E-08 -0.00460242657509724 1.23891152045854E-06"
        rpy="0 0 0" />
      <mass
        value="0.000212134241063242" />
      <inertia
        ixx="2.33719234235661E-09"
        ixy="3.22762522867187E-14"
        ixz="-3.5296103126231E-13"
        iyy="1.52969345561766E-09"
        iyz="-2.85012982590978E-13"
        izz="3.09921927199525E-09" />
    </inertial>
    <visual>
      <origin
        xyz="0 0 0"
        rpy="0 0 0" />
      <geometry>
        <mesh
          filename="package://asar_description/meshes/pitch_link.STL" />
      </geometry>
      <material
        name="">
        <color
          rgba="0.752941176470588 1 0.752941176470588 1" />
      </material>
    </visual>
    <collision>
      <origin
        xyz="0 0 0"
        rpy="0 0 0" />
      <geometry>
        <mesh
          filename="package://asar_description/meshes/pitch_link.STL" />
      </geometry>
    </collision>
  </link>
  <joint
    name="joint_f0_pitch"
    type="revolute">
    <origin
      xyz="0 0 0.28"
      rpy="-1.5708 0 -1.5708" />
    <parent
      link="interface_link" />
    <child
      link="pitch_link" />
    <axis
      xyz="0 0 1" />
    <limit
      lower="-1.570796"
      upper="1.570796"
      effort="1"
      velocity="5.2" />
  </joint>

  <link name="link_collision_0" />

  <joint
    name="joint_collision_0"
    type="fixed">
    <origin
      xyz="0 0 0.14"
      rpy="-1.5708 0 -1.5708" />
    <parent
      link="interface_link" />
    <child
      link="link_collision_0" />
    <axis
      xyz="0 0 1" />
    <limit
      lower="-1.570796"
      upper="1.570796"
      effort="1"
      velocity="5.2" />
  </joint>

  <link
    name="finger_left_link">
    <inertial>
      <origin
        xyz="-0.000728060044408658 -0.00823166125452757 -0.000323786767286641"
        rpy="0 0 0" />
      <mass
        value="0.00013941238132763" />
      <inertia
        ixx="5.12659773643428E-09"
        ixy="-1.58252679742548E-10"
        ixz="1.2677240722727E-11"
        iyy="4.62351522859708E-10"
        iyz="2.54948987001423E-10"
        izz="4.84498957565075E-09" />
    </inertial>
    <visual>
      <origin
        xyz="0 0 0"
        rpy="0 0 0" />
      <geometry>
        <mesh
          filename="package://asar_description/meshes/finger_left_link.STL" />
      </geometry>
      <material
        name="">
        <color
          rgba="1 0.250980392156863 0.12156862745098 1" />
      </material>
    </visual>
    <collision>
      <origin
        xyz="0 0 0"
        rpy="0 0 0" />
      <geometry>
        <mesh
          filename="package://asar_description/meshes/finger_left_link.STL" />
      </geometry>
    </collision>
  </link>
  <joint
    name="joint_f1_finger_left"
    type="revolute">
    <origin
      xyz="0 -0.009 0"
      rpy="0 1.5708 0" />
    <parent
      link="pitch_link" />
    <child
      link="finger_left_link" />
    <axis
      xyz="0 0 1" />
    <limit
      lower="-1.570796"
      upper="1.570796"
      effort="1"
      velocity="5.2" />
  </joint>

  <link name="link_collision_1" />

  <joint
    name="joint_collision_1"
    type="fixed">
    <origin
      xyz="0 -0.01 0.0"
      rpy="0 0 0" />
    <parent
      link="finger_left_link" />
    <child
      link="link_collision_1" />
  </joint>
  <link
    name="finger_right_link">
    <inertial>
      <origin
        xyz="0.000613324471596387 -0.00690795444614234 0.000398239206621067"
        rpy="0 0 0" />
      <mass
        value="0.000166395577602424" />
      <inertia
        ixx="7.09019614386052E-09"
        ixy="3.26224119342583E-10"
        ixz="3.64778078548204E-11"
        iyy="6.20037783086121E-10"
        iyz="-4.2629331679326E-10"
        izz="6.90443851391549E-09" />
    </inertial>
    <visual>
      <origin
        xyz="0 0 0"
        rpy="0 0 0" />
      <geometry>
        <mesh
          filename="package://asar_description/meshes/finger_right_link.STL" />
      </geometry>
      <material
        name="">
        <color
          rgba="0.27843137254902 0.43921568627451 1 1" />
      </material>
    </visual>
    <collision>
      <origin
        xyz="0 0 0"
        rpy="0 0 0" />
      <geometry>
        <mesh
          filename="package://asar_description/meshes/finger_right_link.STL" />
      </geometry>
    </collision>
  </link>
  <joint
    name="joint_f2_finger_right"
    type="revolute">
    <origin
      xyz="0 -0.009 0"
      rpy="0 1.5708 0" />
    <parent
      link="pitch_link" />
    <child
      link="finger_right_link" />
    <axis
      xyz="0 0 -1" />
    <limit
      lower="-1.570796"
      upper="1.570796"
      effort="1"
      velocity="5.2" />
  </joint>
  <link name="ee_link" />
  <joint name="joint_ee" type="fixed">
    <origin xyz="0.002 -0.015 0.0" rpy="0.0 0.0 0.0" />
    <parent link="finger_left_link" />
    <child link="ee_link" />
    <axis xyz="0 0 0" />
  </joint>
  
</robot>
